<?xml version="1.0" encoding="utf-8"?>
<!-- This URDF was automatically created by SolidWorks to URDF Exporter! Originally created by Stephen Brawner (brawner@gmail.com) 
     Commit Version: 1.6.0-4-g7f85cfe  Build Version: 1.6.7995.38578
     For more information, please see http://wiki.ros.org/sw_urdf_exporter -->
<robot
  name="arm_assembly">
  <link
    name="base_link">
    <inertial>
      <origin
        xyz="0.0097440197564995 4.33680868994202E-18 -0.0246719054070537"
        rpy="0 0 0" />
      <mass
        value="0.0313441907558178" />
      <inertia
        ixx="4.5678163619065E-06"
        ixy="2.7395113303751E-22"
        ixz="7.56580208230383E-08"
        iyy="7.88177129027588E-06"
        iyz="1.47295558878883E-22"
        izz="5.3555618171031E-06" />
    </inertial>
    <visual>
      <origin
        xyz="0 0 0"
        rpy="0 0 0" />
      <geometry>
        <mesh
          filename="package://arm_assembly/meshes/base_link.STL" />
      </geometry>
      <material
        name="">
        <color
          rgba="0.752941176470588 0.752941176470588 0.752941176470588 1" />
      </material>
    </visual>
    <collision>
      <origin
        xyz="0 0 0"
        rpy="0 0 0" />
      <geometry>
        <mesh
          filename="package://arm_assembly/meshes/base_link.STL" />
      </geometry>
    </collision>
  </link>
  <link
    name="waist_link">
    <inertial>
      <origin
        xyz="0.00437594951239964 0.00935961819595053 0.0016588047211646"
        rpy="0 0 0" />
      <mass
        value="0.0986381291251367" />
      <inertia
        ixx="5.12001141639425E-05"
        ixy="-5.87323460764985E-07"
        ixz="-7.8982030556206E-06"
        iyy="6.34361781394893E-05"
        iyz="-5.11350329063061E-06"
        izz="6.08798554414956E-05" />
    </inertial>
    <visual>
      <origin
        xyz="0 0 0"
        rpy="0 0 0" />
      <geometry>
        <mesh
          filename="package://arm_assembly/meshes/waist_link.STL" />
      </geometry>
      <material
        name="">
        <color
          rgba="0.752941176470588 0.752941176470588 0.752941176470588 1" />
      </material>
    </visual>
    <collision>
      <origin
        xyz="0 0 0"
        rpy="0 0 0" />
      <geometry>
        <mesh
          filename="package://arm_assembly/meshes/waist_link.STL" />
      </geometry>
    </collision>
  </link>
  <joint
    name="joint1"
    type="continuous">
    <origin
      xyz="-0.0012854 0.004 0.020614"
      rpy="0 0 0" />
    <parent
      link="base_link" />
    <child
      link="waist_link" />
    <axis
      xyz="0 0 -1" />
  </joint>
  <link
    name="arm1_link">
    <inertial>
      <origin
        xyz="-0.000127471988273002 -0.00755473194721562 0.058585025591689"
        rpy="0 0 0" />
      <mass
        value="0.0659056350151601" />
      <inertia
        ixx="0.000107110770778727"
        ixy="-4.72987282679317E-10"
        ixz="-3.03283572378026E-09"
        iyy="0.000111920103634365"
        iyz="-2.15990317156758E-07"
        izz="9.16885453329861E-06" />
    </inertial>
    <visual>
      <origin
        xyz="0 0 0"
        rpy="0 0 0" />
      <geometry>
        <mesh
          filename="package://arm_assembly/meshes/arm1_link.STL" />
      </geometry>
      <material
        name="">
        <color
          rgba="0.752941176470588 0.752941176470588 0.752941176470588 1" />
      </material>
    </visual>
    <collision>
      <origin
        xyz="0 0 0"
        rpy="0 0 0" />
      <geometry>
        <mesh
          filename="package://arm_assembly/meshes/arm1_link.STL" />
      </geometry>
    </collision>
  </link>
  <joint
    name="joint2"
    type="continuous">
    <origin
      xyz="0.015204 0 0.019662"
      rpy="0 0 0" />
    <parent
      link="waist_link" />
    <child
      link="arm1_link" />
    <axis
      xyz="0 -1 0" />
  </joint>
  <link
    name="arm2_link">
    <inertial>
      <origin
        xyz="-4.12554406102571E-05 0.0123526401588072 0.0317323258483413"
        rpy="0 0 0" />
      <mass
        value="0.0939634772458711" />
      <inertia
        ixx="6.31700859373996E-05"
        ixy="-1.41279958113452E-09"
        ixz="-2.95607650976687E-08"
        iyy="6.41735629182009E-05"
        iyz="-3.16064327101628E-07"
        izz="1.50896923779467E-05" />
    </inertial>
    <visual>
      <origin
        xyz="0 0 0"
        rpy="0 0 0" />
      <geometry>
        <mesh
          filename="package://arm_assembly/meshes/arm2_link.STL" />
      </geometry>
      <material
        name="">
        <color
          rgba="0.752941176470588 0.752941176470588 0.752941176470588 1" />
      </material>
    </visual>
    <collision>
      <origin
        xyz="0 0 0"
        rpy="0 0 0" />
      <geometry>
        <mesh
          filename="package://arm_assembly/meshes/arm2_link.STL" />
      </geometry>
    </collision>
  </link>
  <joint
    name="joint3"
    type="continuous">
    <origin
      xyz="0 0 0.12"
      rpy="0 0 0" />
    <parent
      link="arm1_link" />
    <child
      link="arm2_link" />
    <axis
      xyz="0 -1 0" />
  </joint>
  <link
    name="arm3_link">
    <inertial>
      <origin
        xyz="-0.00503335394999915 -0.00300070197708 0.0195087845857629"
        rpy="0 0 0" />
      <mass
        value="0.0234826220419238" />
      <inertia
        ixx="4.62571316029344E-06"
        ixy="4.10074956405484E-09"
        ixz="-1.10019838636368E-08"
        iyy="5.40770744087351E-06"
        iyz="6.17474889771245E-07"
        izz="3.10214921540411E-06" />
    </inertial>
    <visual>
      <origin
        xyz="0 0 0"
        rpy="0 0 0" />
      <geometry>
        <mesh
          filename="package://arm_assembly/meshes/arm3_link.STL" />
      </geometry>
      <material
        name="">
        <color
          rgba="0.752941176470588 0.752941176470588 0.752941176470588 1" />
      </material>
    </visual>
    <collision>
      <origin
        xyz="0 0 0"
        rpy="0 0 0" />
      <geometry>
        <mesh
          filename="package://arm_assembly/meshes/arm3_link.STL" />
      </geometry>
    </collision>
  </link>
  <joint
    name="joint4"
    type="continuous">
    <origin
      xyz="-0.0053 0.007 0.09375"
      rpy="0 0 0" />
    <parent
      link="arm2_link" />
    <child
      link="arm3_link" />
    <axis
      xyz="0 0 1" />
  </joint>
  <link
    name="gripper_link">
    <inertial>
      <origin
        xyz="-0.00906978262645251 -0.0126496793942134 0.0488635804088527"
        rpy="0 0 0" />
      <mass
        value="0.0420479280472721" />
      <inertia
        ixx="1.32056806324632E-05"
        ixy="3.99217032169249E-07"
        ixz="1.44271148728466E-06"
        iyy="1.18089301485161E-05"
        iyz="-1.38288738509686E-06"
        izz="4.01578213742469E-06" />
    </inertial>
    <visual>
      <origin
        xyz="0 0 0"
        rpy="0 0 0" />
      <geometry>
        <mesh
          filename="package://arm_assembly/meshes/gripper_link.STL" />
      </geometry>
      <material
        name="">
        <color
          rgba="0.752941176470588 0.752941176470588 0.752941176470588 1" />
      </material>
    </visual>
    <collision>
      <origin
        xyz="0 0 0"
        rpy="0 0 0" />
      <geometry>
        <mesh
          filename="package://arm_assembly/meshes/gripper_link.STL" />
      </geometry>
    </collision>
  </link>
  <joint
    name="joint5"
    type="continuous">
    <origin
      xyz="-0.005 0 0.028"
      rpy="0 0 0" />
    <parent
      link="arm3_link" />
    <child
      link="gripper_link" />
    <axis
      xyz="0 1 0" />
  </joint>
</robot>